Workbook

Sheet README
A1: Scam Shield - cybersecurity awareness impact evaluation
A2: README and assumptions
A3: Purpose: pre/post evaluation of two cybersecurity-awareness interventions.
A4: Social media scenario: 47 participants. Seminar scenario: 43 students. Participant IDs match across Pre and Post sheets.
A5: Quiz: 12 questions, 3 per topic. Pre and Post use parallel versions (form A / form B) of the same learning objective, with equal assumed difficulty. Each question is worth 1 point.
A6: The live quiz app presents some of these questions as interactive tasks (match the lines, scam-or-safe swipe cards, tap the red flags, put steps in order). Question_Bank holds the four-option form of each learning objective that the responses are modelled on; each task is scored right or wrong on the same objective.
A8: Assumptions used to generate the responses (see analysis/generate_data.py)
A9: 1. Each participant has a random baseline ability; each question has a fixed difficulty; correctness is a probability from both, so scores are noisy and not uniformly high.
A10: 2. Each participant has a random personal gain for the intervention, so some improve a lot, some a little, and some score lower after.
A11: 3. Seminar gain is assumed larger on average than the social media gain (direct instruction and discussion).
A12: 4. Two questions (QR-code phishing, digital arrest) are assumed stubborn: interventions help them less, especially the social posts. Social posts are assumed to help WhatsApp scam awareness slightly more than everyday-fraud awareness.
A13: 5. Wrong answers are chosen uniformly among the three incorrect options.
... A18: Improvement categories (change in questions correct): Substantial >= 3, Modest 1-2, Unchanged 0, Lower < 0. Thresholds are editable in cells B23:B24 on each analysis sheet.

Sheet Social_Pre
A1: Scam Shield - cybersecurity awareness impact evaluation
A2: Participant_ID | B2: Intervention_Group | C2: Assessment_Stage | D2: Question_ID | E2: Topic | F2: Selected_Answer | G2: Correct_Answer | H2: Is_Correct | I2: Question_Score | J2: Overall_Score | K2: Overall_Pct | L2: Topic_Accuracy | M2: Participant_Name
A3: SM001 | B3: Social Media Campaign | C3: Pre | D3: Q01 | E3: WhatsApp Scams | F3: A | G3: =INDEX(Question_Bank!$G$3:$G$14,MATCH(D3,Question_Bank!$A$3:$A$14,0)) -> 0 | H3: =IF(F3=G3,1,0) -> 0 | I3: =H3*INDEX(Question_Bank!$M$3:$M$14,MATCH(D3,Question_Bank!$A$3:$A$14,0)) -> 0 | J3: =SUMIFS($I$3:$I$566,$A$3:$A$566,A3) -> 0 | K3: =J3/SUM(Question_Bank!$M$3:$M$14) -> 0 | L3: =SUMIFS($I$3:$I$566,$A$3:$A$566,A3,$E$3:$E$566,E3)/SUMIFS(Question_Bank!$M$3:$M$14,Question_Bank!$B$3:$B$14,E3) -> 0 | M3: Zaid Bhatia
A4: SM001 | B4: Social Media Campaign | C4: Pre | D4: Q02 | E4: WhatsApp Scams | F4: D | G4: =INDEX(Question_Bank!$G$3:$G$14,MATCH(D4,Question_Bank!$A$3:$A$14,0)) -> 0 | H4: =IF(F4=G4,1,0) -> 0 | I4: =H4*INDEX(Question_Bank!$M$3:$M$14,MATCH(D4,Question_Bank!$A$3:$A$14,0)) -> 0 | J4: =SUMIFS($I$3:$I$566,$A$3:$A$566,A4) -> 0 | K4: =J4/SUM(Question_Bank!$M$3:$M$14) -> 0 | L4: =SUMIFS($I$3:$I$566,$A$3:$A$566,A4,$E$3:$E$566,E4)/SUMIFS(Question_Bank!$M$3:$M$14,Question_Bank!$B$3:$B$14,E4) -> 0 | M4: Zaid Bhatia
A5: SM001 | B5: Social Media Campaign | C5: Pre | D5: Q03 | E5: WhatsApp Scams | F5: B | G5: =INDEX(Question_Bank!$G$3:$G$14,MATCH(D5,Question_Bank!$A$3:$A$14,0)) -> 0 | H5: =IF(F5=G5,1,0) -> 0 | I5: =H5*INDEX(Question_Bank!$M$3:$M$14,MATCH(D5,Question_Bank!$A$3:$A$14,0)) -> 0 | J5: =SUMIFS($I$3:$I$566,$A$3:$A$566,A5) -> 0 | K5: =J5/SUM(Question_Bank!$M$3:$M$14) -> 0 | L5: =SUMIFS($I$3:$I$566,$A$3:$A$566,A5,$E$3:$E$566,E5)/SUMIFS(Question_Bank!$M$3:$M$14,Question_Bank!$B$3:$B$14,E5) -> 0 | M5: Zaid Bhatia
A6: SM001 | B6: Social Media Campaign | C6: Pre | D6: Q04 | E6: Phishing | F6: A | G6: =INDEX(Question_Bank!$G$3:$G$14,MATCH(D6,Question_Bank!$A$3:$A$14,0)) -> 0 | H6: =IF(F6=G6,1,0) -> 0 | I6: =H6*INDEX(Question_Bank!$M$3:$M$14,MATCH(D6,Question_Bank!$A$3:$A$14,0)) -> 0 | J6: =SUMIFS($I$3:$I$566,$A$3:$A$566,A6) -> 0 | K6: =J6/SUM(Question_Bank!$M$3:$M$14) -> 0 | L6: =SUMIFS($I$3:$I$566,$A$3:$A$566,A6,$E$3:$E$566,E6)/SUMIFS(Question_Bank!$M$3:$M$14,Question_Bank!$B$3:$B$14,E6) -> 0 | M6: Zaid Bhatia
A7: SM001 | B7: Social Media Campaign | C7: Pre | D7: Q05 | E7: Phishing | F7: B | G7: =INDEX(Question_Bank!$G$3:$G$14,MATCH(D7,Question_Bank!$A$3:$A$14,0)) -> 0 | H7: =IF(F7=G7,1,0) -> 0 | I7: =H7*INDEX(Question_Bank!$M$3:$M$14,MATCH(D7,Question_Bank!$A$3:$A$14,0)) -> 0 | J7: =SUMIFS($I$3:$I$566,$A$3:$A$566,A7) -> 0 | K7: =J7/SUM(Question_Bank!$M$3:$M$14) -> 0 | L7: =SUMIFS($I$3:$I$566,$A$3:$A$566,A7,$E$3:$E$566,E7)/SUMIFS(Question_Bank!$M$3:$M$14,Question_Bank!$B$3:$B$14,E7) -> 0 | M7: Zaid Bhatia
A8: SM001 | B8: Social Media Campaign | C8: Pre | D8: Q06 | E8: Phishing | F8: B | G8: =INDEX(Question_Bank!$G$3:$G$14,MATCH(D8,Question_Bank!$A$3:$A$14,0)) -> 0 | H8: =IF(F8=G8,1,0) -> 0 | I8: =H8*INDEX(Question_Bank!$M$3:$M$14,MATCH(D8,Question_Bank!$A$3:$A$14,0)) -> 0 | J8: =SUMIFS($I$3:$I$566,$A$3:$A$566,A8) -> 0 | K8: =J8/SUM(Question_Bank!$M$3:$M$14) -> 0 | L8: =SUMIFS($I$3:$I$566,$A$3:$A$566,A8,$E$3:$E$566,E8)/SUMIFS(Question_Bank!$M$3:$M$14,Question_Bank!$B$3:$B$14,E8) -> 0 | M8: Zaid Bhatia
A9: SM001 | B9: Social Media Campaign | C9: Pre | D9: Q07 | E9: Everyday Online Fraud | F9: A | G9: =INDEX(Question_Bank!$G$3:$G$14,MATCH(D9,Question_Bank!$A$3:$A$14,0)) -> 0 | H9: =IF(F9=G9,1,0) -> 0 | I9: =H9*INDEX(Question_Bank!$M$3:$M$14,MATCH(D9,Question_Bank!$A$3:$A$14,0)) -> 0 | J9: =SUMIFS($I$3:$I$566,$A$3:$A$566,A9) -> 0 | K9: =J9/SUM(Question_Bank!$M$3:$M$14) -> 0 | L9: =SUMIFS($I$3:$I$566,$A$3:$A$566,A9,$E$3:$E$566,E9)/SUMIFS(Question_Bank!$M$3:$M$14,Question_Bank!$B$3:$B$14,E9) -> 0 | M9: Zaid Bhatia
A10: SM001 | B10: Social Media Campaign | C10: Pre | D10: Q08 | E10: Everyday Online Fraud | F10: B | G10: =INDEX(Question_Bank!$G$3:$G$14,MATCH(D10,Question_Bank!$A$3:$A$14,0)) -> 0 | H10: =IF(F10=G10,1,0) -> 0 | I10: =H10*INDEX(Question_Bank!$M$3:$M$14,MATCH(D10,Question_Bank!$A$3:$A$14,0)) -> 0 | J10: =SUMIFS($I$3:$I$566,$A$3:$A$566,A10) -> 0 | K10: =J10/SUM(Question_Bank!$M$3:$M$14) -> 0 | L10: =SUMIFS($I$3:$I$566,$A$3:$A$566,A10,$E$3:$E$566,E10)/SUMIFS(Question_Bank!$M$3:$M$14,Question_Bank!$B$3:$B$14,E10) -> 0 | M10: Zaid Bhatia
A11: SM001 | B11: Social Media Campaign | C11: Pre | D11: Q09 | E11: Everyday Online Fraud | F11: A | G11: =INDEX(Question_Bank!$G$3:$G$14,MATCH(D11,Question_Bank!$A$3:$A$14,0)) -> 0 | H11: =IF(F11=G11,1,0) -> 0 | I11: =H11*INDEX(Question_Bank!$M$3:$M$14,MATCH(D11,Question_Bank!$A$3:$A$14,0)) -> 0 | J11: =SUMIFS($I$3:$I$566,$A$3:$A$566,A11) -> 0 | K11: =J11/SUM(Question_Bank!$M$3:$M$14) -> 0 | L11: =SUMIFS($I$3:$I$566,$A$3:$A$566,A11,$E$3:$E$566,E11)/SUMIFS(Question_Bank!$M$3:$M$14,Question_Bank!$B$3:$B$14,E11) -> 0 | M11: Zaid Bhatia
A12: SM001 | B12: Social Media Campaign | C12: Pre | D12: Q10 | E12: Scam Prevention | F12: B | G12: =INDEX(Question_Bank!$G$3:$G$14,MATCH(D12,Question_Bank!$A$3:$A$14,0)) -> 0 | H12: =IF(F12=G12,1,0) -> 0 | I12: =H12*INDEX(Question_Bank!$M$3:$M$14,MATCH(D12,Question_Bank!$A$3:$A$14,0)) -> 0 | J12: =SUMIFS($I$3:$I$566,$A$3:$A$566,A12) -> 0 | K12: =J12/SUM(Question_Bank!$M$3:$M$14) -> 0 | L12: =SUMIFS($I$3:$I$566,$A$3:$A$566,A12,$E$3:$E$566,E12)/SUMIFS(Question_Bank!$M$3:$M$14,Question_Bank!$B$3:$B$14,E12) -> 0 | M12: Zaid Bhatia
A13: SM001 | B13: Social Media Campaign | C13: Pre | D13: Q11 | E13: Scam Prevention | F13: C | G13: =INDEX(Question_Bank!$G$3:$G$14,MATCH(D13,Question_Bank!$A$3:$A$14,0)) -> 0 | H13: =IF(F13=G13,1,0) -> 0 | I13: =H13*INDEX(Question_Bank!$M$3:$M$14,MATCH(D13,Question_Bank!$A$3:$A$14,0)) -> 0 | J13: =SUMIFS($I$3:$I$566,$A$3:$A$566,A13) -> 0 | K13: =J13/SUM(Question_Bank!$M$3:$M$14) -> 0 | L13: =SUMIFS($I$3:$I$566,$A$3:$A$566,A13,$E$3:$E$566,E13)/SUMIFS(Question_Bank!$M$3:$M$14,Question_Bank!$B$3:$B$14,E13) -> 0 | M13: Zaid Bhatia
A14: SM001 | B14: Social Media Campaign | C14: Pre | D14: Q12 | E14: Scam Prevention | F14: D | G14: =INDEX(Question_Bank!$G$3:$G$14,MATCH(D14,Question_Bank!$A$3:$A$14,0)) -> 0 | H14: =IF(F14=G14,1,0) -> 0 | I14: =H14*INDEX(Question_Bank!$M$3:$M$14,MATCH(D14,Question_Bank!$A$3:$A$14,0)) -> 0 | J14: =SUMIFS($I$3:$I$566,$A$3:$A$566,A14) -> 0 | K14: =J14/SUM(Question_Bank!$M$3:$M$14) -> 0 | L14: =SUMIFS($I$3:$I$566,$A$3:$A$566,A14,$E$3:$E$566,E14)/SUMIFS(Question_Bank!$M$3:$M$14,Question_Bank!$B$3:$B$14,E14) -> 0 | M14: Zaid Bhatia
... A566: SM047 | B566: Social Media Campaign | C566: Pre | D566: Q12 | E566: Scam Prevention | F566: B | G566: =INDEX(Question_Bank!$G$3:$G$14,MATCH(D566,Question_Bank!$A$3:$A$14,0)) -> 0 | H566: =IF(F566=G566,1,0) -> 0 | I566: =H566*INDEX(Question_Bank!$M$3:$M$14,MATCH(D566,Question_Bank!$A$3:$A$14,0)) -> 0 | J566: =SUMIFS($I$3:$I$566,$A$3:$A$566,A566) -> 0 | K566: =J566/SUM(Question_Bank!$M$3:$M$14) -> 0 | L566: =SUMIFS($I$3:$I$566,$A$3:$A$566,A566,$E$3:$E$566,E566)/SUMIFS(Question_Bank!$M$3:$M$14,Question_Bank!$B$3:$B$14,E566) -> 0 | M566: Neha Patel

Sheet Social_Post
A1: Scam Shield - cybersecurity awareness impact evaluation
A2: Participant_ID | B2: Intervention_Group | C2: Assessment_Stage | D2: Question_ID | E2: Topic | F2: Selected_Answer | G2: Correct_Answer | H2: Is_Correct | I2: Question_Score | J2: Overall_Score | K2: Overall_Pct | L2: Topic_Accuracy | M2: Participant_Name
A3: SM001 | B3: Social Media Campaign | C3: Post | D3: Q01 | E3: WhatsApp Scams | F3: C | G3: =INDEX(Question_Bank!$J$3:$J$14,MATCH(D3,Question_Bank!$A$3:$A$14,0)) -> 0 | H3: =IF(F3=G3,1,0) -> 0 | I3: =H3*INDEX(Question_Bank!$M$3:$M$14,MATCH(D3,Question_Bank!$A$3:$A$14,0)) -> 0 | J3: =SUMIFS($I$3:$I$566,$A$3:$A$566,A3) -> 0 | K3: =J3/SUM(Question_Bank!$M$3:$M$14) -> 0 | L3: =SUMIFS($I$3:$I$566,$A$3:$A$566,A3,$E$3:$E$566,E3)/SUMIFS(Question_Bank!$M$3:$M$14,Question_Bank!$B$3:$B$14,E3) -> 0 | M3: Zaid Bhatia
A4: SM001 | B4: Social Media Campaign | C4: Post | D4: Q02 | E4: WhatsApp Scams | F4: D | G4: =INDEX(Question_Bank!$J$3:$J$14,MATCH(D4,Question_Bank!$A$3:$A$14,0)) -> 0 | H4: =IF(F4=G4,1,0) -> 0 | I4: =H4*INDEX(Question_Bank!$M$3:$M$14,MATCH(D4,Question_Bank!$A$3:$A$14,0)) -> 0 | J4: =SUMIFS($I$3:$I$566,$A$3:$A$566,A4) -> 0 | K4: =J4/SUM(Question_Bank!$M$3:$M$14) -> 0 | L4: =SUMIFS($I$3:$I$566,$A$3:$A$566,A4,$E$3:$E$566,E4)/SUMIFS(Question_Bank!$M$3:$M$14,Question_Bank!$B$3:$B$14,E4) -> 0 | M4: Zaid Bhatia
A5: SM001 | B5: Social Media Campaign | C5: Post | D5: Q03 | E5: WhatsApp Scams | F5: A | G5: =INDEX(Question_Bank!$J$3:$J$14,MATCH(D5,Question_Bank!$A$3:$A$14,0)) -> 0 | H5: =IF(F5=G5,1,0) -> 0 | I5: =H5*INDEX(Question_Bank!$M$3:$M$14,MATCH(D5,Question_Bank!$A$3:$A$14,0)) -> 0 | J5: =SUMIFS($I$3:$I$566,$A$3:$A$566,A5) -> 0 | K5: =J5/SUM(Question_Bank!$M$3:$M$14) -> 0 | L5: =SUMIFS($I$3:$I$566,$A$3:$A$566,A5,$E$3:$E$566,E5)/SUMIFS(Question_Bank!$M$3:$M$14,Question_Bank!$B$3:$B$14,E5) -> 0 | M5: Zaid Bhatia
A6: SM001 | B6: Social Media Campaign | C6: Post | D6: Q04 | E6: Phishing | F6: B | G6: =INDEX(Question_Bank!$J$3:$J$14,MATCH(D6,Question_Bank!$A$3:$A$14,0)) -> 0 | H6: =IF(F6=G6,1,0) -> 0 | I6: =H6*INDEX(Question_Bank!$M$3:$M$14,MATCH(D6,Question_Bank!$A$3:$A$14,0)) -> 0 | J6: =SUMIFS($I$3:$I$566,$A$3:$A$566,A6) -> 0 | K6: =J6/SUM(Question_Bank!$M$3:$M$14) -> 0 | L6: =SUMIFS($I$3:$I$566,$A$3:$A$566,A6,$E$3:$E$566,E6)/SUMIFS(Question_Bank!$M$3:$M$14,Question_Bank!$B$3:$B$14,E6) -> 0 | M6: Zaid Bhatia
A7: SM001 | B7: Social Media Campaign | C7: Post | D7: Q05 | E7: Phishing | F7: B | G7: =INDEX(Question_Bank!$J$3:$J$14,MATCH(D7,Question_Bank!$A$3:$A$14,0)) -> 0 | H7: =IF(F7=G7,1,0) -> 0 | I7: =H7*INDEX(Question_Bank!$M$3:$M$14,MATCH(D7,Question_Bank!$A$3:$A$14,0)) -> 0 | J7: =SUMIFS($I$3:$I$566,$A$3:$A$566,A7) -> 0 | K7: =J7/SUM(Question_Bank!$M$3:$M$14) -> 0 | L7: =SUMIFS($I$3:$I$566,$A$3:$A$566,A7,$E$3:$E$566,E7)/SUMIFS(Question_Bank!$M$3:$M$14,Question_Bank!$B$3:$B$14,E7) -> 0 | M7: Zaid Bhatia
A8: SM001 | B8: Social Media Campaign | C8: Post | D8: Q06 | E8: Phishing | F8: D | G8: =INDEX(Question_Bank!$J$3:$J$14,MATCH(D8,Question_Bank!$A$3:$A$14,0)) -> 0 | H8: =IF(F8=G8,1,0) -> 0 | I8: =H8*INDEX(Question_Bank!$M$3:$M$14,MATCH(D8,Question_Bank!$A$3:$A$14,0)) -> 0 | J8: =SUMIFS($I$3:$I$566,$A$3:$A$566,A8) -> 0 | K8: =J8/SUM(Question_Bank!$M$3:$M$14) -> 0 | L8: =SUMIFS($I$3:$I$566,$A$3:$A$566,A8,$E$3:$E$566,E8)/SUMIFS(Question_Bank!$M$3:$M$14,Question_Bank!$B$3:$B$14,E8) -> 0 | M8: Zaid Bhatia
A9: SM001 | B9: Social Media Campaign | C9: Post | D9: Q07 | E9: Everyday Online Fraud | F9: A | G9: =INDEX(Question_Bank!$J$3:$J$14,MATCH(D9,Question_Bank!$A$3:$A$14,0)) -> 0 | H9: =IF(F9=G9,1,0) -> 0 | I9: =H9*INDEX(Question_Bank!$M$3:$M$14,MATCH(D9,Question_Bank!$A$3:$A$14,0)) -> 0 | J9: =SUMIFS($I$3:$I$566,$A$3:$A$566,A9) -> 0 | K9: =J9/SUM(Question_Bank!$M$3:$M$14) -> 0 | L9: =SUMIFS($I$3:$I$566,$A$3:$A$566,A9,$E$3:$E$566,E9)/SUMIFS(Question_Bank!$M$3:$M$14,Question_Bank!$B$3:$B$14,E9) -> 0 | M9: Zaid Bhatia
A10: SM001 | B10: Social Media Campaign | C10: Post | D10: Q08 | E10: Everyday Online Fraud | F10: D | G10: =INDEX(Question_Bank!$J$3:$J$14,MATCH(D10,Question_Bank!$A$3:$A$14,0)) -> 0 | H10: =IF(F10=G10,1,0) -> 0 | I10: =H10*INDEX(Question_Bank!$M$3:$M$14,MATCH(D10,Question_Bank!$A$3:$A$14,0)) -> 0 | J10: =SUMIFS($I$3:$I$566,$A$3:$A$566,A10) -> 0 | K10: =J10/SUM(Question_Bank!$M$3:$M$14) -> 0 | L10: =SUMIFS($I$3:$I$566,$A$3:$A$566,A10,$E$3:$E$566,E10)/SUMIFS(Question_Bank!$M$3:$M$14,Question_Bank!$B$3:$B$14,E10) -> 0 | M10: Zaid Bhatia
A11: SM001 | B11: Social Media Campaign | C11: Post | D11: Q09 | E11: Everyday Online Fraud | F11: C | G11: =INDEX(Question_Bank!$J$3:$J$14,MATCH(D11,Question_Bank!$A$3:$A$14,0)) -> 0 | H11: =IF(F11=G11,1,0) -> 0 | I11: =H11*INDEX(Question_Bank!$M$3:$M$14,MATCH(D11,Question_Bank!$A$3:$A$14,0)) -> 0 | J11: =SUMIFS($I$3:$I$566,$A$3:$A$566,A11) -> 0 | K11: =J11/SUM(Question_Bank!$M$3:$M$14) -> 0 | L11: =SUMIFS($I$3:$I$566,$A$3:$A$566,A11,$E$3:$E$566,E11)/SUMIFS(Question_Bank!$M$3:$M$14,Question_Bank!$B$3:$B$14,E11) -> 0 | M11: Zaid Bhatia
A12: SM001 | B12: Social Media Campaign | C12: Post | D12: Q10 | E12: Scam Prevention | F12: D | G12: =INDEX(Question_Bank!$J$3:$J$14,MATCH(D12,Question_Bank!$A$3:$A$14,0)) -> 0 | H12: =IF(F12=G12,1,0) -> 0 | I12: =H12*INDEX(Question_Bank!$M$3:$M$14,MATCH(D12,Question_Bank!$A$3:$A$14,0)) -> 0 | J12: =SUMIFS($I$3:$I$566,$A$3:$A$566,A12) -> 0 | K12: =J12/SUM(Question_Bank!$M$3:$M$14) -> 0 | L12: =SUMIFS($I$3:$I$566,$A$3:$A$566,A12,$E$3:$E$566,E12)/SUMIFS(Question_Bank!$M$3:$M$14,Question_Bank!$B$3:$B$14,E12) -> 0 | M12: Zaid Bhatia
A13: SM001 | B13: Social Media Campaign | C13: Post | D13: Q11 | E13: Scam Prevention | F13: D | G13: =INDEX(Question_Bank!$J$3:$J$14,MATCH(D13,Question_Bank!$A$3:$A$14,0)) -> 0 | H13: =IF(F13=G13,1,0) -> 0 | I13: =H13*INDEX(Question_Bank!$M$3:$M$14,MATCH(D13,Question_Bank!$A$3:$A$14,0)) -> 0 | J13: =SUMIFS($I$3:$I$566,$A$3:$A$566,A13) -> 0 | K13: =J13/SUM(Question_Bank!$M$3:$M$14) -> 0 | L13: =SUMIFS($I$3:$I$566,$A$3:$A$566,A13,$E$3:$E$566,E13)/SUMIFS(Question_Bank!$M$3:$M$14,Question_Bank!$B$3:$B$14,E13) -> 0 | M13: Zaid Bhatia
A14: SM001 | B14: Social Media Campaign | C14: Post | D14: Q12 | E14: Scam Prevention | F14: B | G14: =INDEX(Question_Bank!$J$3:$J$14,MATCH(D14,Question_Bank!$A$3:$A$14,0)) -> 0 | H14: =IF(F14=G14,1,0) -> 0 | I14: =H14*INDEX(Question_Bank!$M$3:$M$14,MATCH(D14,Question_Bank!$A$3:$A$14,0)) -> 0 | J14: =SUMIFS($I$3:$I$566,$A$3:$A$566,A14) -> 0 | K14: =J14/SUM(Question_Bank!$M$3:$M$14) -> 0 | L14: =SUMIFS($I$3:$I$566,$A$3:$A$566,A14,$E$3:$E$566,E14)/SUMIFS(Question_Bank!$M$3:$M$14,Question_Bank!$B$3:$B$14,E14) -> 0 | M14: Zaid Bhatia
... A566: SM047 | B566: Social Media Campaign | C566: Post | D566: Q12 | E566: Scam Prevention | F566: A | G566: =INDEX(Question_Bank!$J$3:$J$14,MATCH(D566,Question_Bank!$A$3:$A$14,0)) -> 0 | H566: =IF(F566=G566,1,0) -> 0 | I566: =H566*INDEX(Question_Bank!$M$3:$M$14,MATCH(D566,Question_Bank!$A$3:$A$14,0)) -> 0 | J566: =SUMIFS($I$3:$I$566,$A$3:$A$566,A566) -> 0 | K566: =J566/SUM(Question_Bank!$M$3:$M$14) -> 0 | L566: =SUMIFS($I$3:$I$566,$A$3:$A$566,A566,$E$3:$E$566,E566)/SUMIFS(Question_Bank!$M$3:$M$14,Question_Bank!$B$3:$B$14,E566) -> 0 | M566: Neha Patel

Sheet Seminar_Pre
A1: Scam Shield - cybersecurity awareness impact evaluation
A2: Participant_ID | B2: Intervention_Group | C2: Assessment_Stage | D2: Question_ID | E2: Topic | F2: Selected_Answer | G2: Correct_Answer | H2: Is_Correct | I2: Question_Score | J2: Overall_Score | K2: Overall_Pct | L2: Topic_Accuracy | M2: Participant_Name
A3: SEM001 | B3: In-Person Seminar | C3: Pre | D3: Q01 | E3: WhatsApp Scams | F3: A | G3: =INDEX(Question_Bank!$G$3:$G$14,MATCH(D3,Question_Bank!$A$3:$A$14,0)) -> 0 | H3: =IF(F3=G3,1,0) -> 0 | I3: =H3*INDEX(Question_Bank!$M$3:$M$14,MATCH(D3,Question_Bank!$A$3:$A$14,0)) -> 0 | J3: =SUMIFS($I$3:$I$518,$A$3:$A$518,A3) -> 0 | K3: =J3/SUM(Question_Bank!$M$3:$M$14) -> 0 | L3: =SUMIFS($I$3:$I$518,$A$3:$A$518,A3,$E$3:$E$518,E3)/SUMIFS(Question_Bank!$M$3:$M$14,Question_Bank!$B$3:$B$14,E3) -> 0 | M3: Zaid Khan
A4: SEM001 | B4: In-Person Seminar | C4: Pre | D4: Q02 | E4: WhatsApp Scams | F4: A | G4: =INDEX(Question_Bank!$G$3:$G$14,MATCH(D4,Question_Bank!$A$3:$A$14,0)) -> 0 | H4: =IF(F4=G4,1,0) -> 0 | I4: =H4*INDEX(Question_Bank!$M$3:$M$14,MATCH(D4,Question_Bank!$A$3:$A$14,0)) -> 0 | J4: =SUMIFS($I$3:$I$518,$A$3:$A$518,A4) -> 0 | K4: =J4/SUM(Question_Bank!$M$3:$M$14) -> 0 | L4: =SUMIFS($I$3:$I$518,$A$3:$A$518,A4,$E$3:$E$518,E4)/SUMIFS(Question_Bank!$M$3:$M$14,Question_Bank!$B$3:$B$14,E4) -> 0 | M4: Zaid Khan
A5: SEM001 | B5: In-Person Seminar | C5: Pre | D5: Q03 | E5: WhatsApp Scams | F5: D | G5: =INDEX(Question_Bank!$G$3:$G$14,MATCH(D5,Question_Bank!$A$3:$A$14,0)) -> 0 | H5: =IF(F5=G5,1,0) -> 0 | I5: =H5*INDEX(Question_Bank!$M$3:$M$14,MATCH(D5,Question_Bank!$A$3:$A$14,0)) -> 0 | J5: =SUMIFS($I$3:$I$518,$A$3:$A$518,A5) -> 0 | K5: =J5/SUM(Question_Bank!$M$3:$M$14) -> 0 | L5: =SUMIFS($I$3:$I$518,$A$3:$A$518,A5,$E$3:$E$518,E5)/SUMIFS(Question_Bank!$M$3:$M$14,Question_Bank!$B$3:$B$14,E5) -> 0 | M5: Zaid Khan
A6: SEM001 | B6: In-Person Seminar | C6: Pre | D6: Q04 | E6: Phishing | F6: C | G6: =INDEX(Question_Bank!$G$3:$G$14,MATCH(D6,Question_Bank!$A$3:$A$14,0)) -> 0 | H6: =IF(F6=G6,1,0) -> 0 | I6: =H6*INDEX(Question_Bank!$M$3:$M$14,MATCH(D6,Question_Bank!$A$3:$A$14,0)) -> 0 | J6: =SUMIFS($I$3:$I$518,$A$3:$A$518,A6) -> 0 | K6: =J6/SUM(Question_Bank!$M$3:$M$14) -> 0 | L6: =SUMIFS($I$3:$I$518,$A$3:$A$518,A6,$E$3:$E$518,E6)/SUMIFS(Question_Bank!$M$3:$M$14,Question_Bank!$B$3:$B$14,E6) -> 0 | M6: Zaid Khan
A7: SEM001 | B7: In-Person Seminar | C7: Pre | D7: Q05 | E7: Phishing | F7: C | G7: =INDEX(Question_Bank!$G$3:$G$14,MATCH(D7,Question_Bank!$A$3:$A$14,0)) -> 0 | H7: =IF(F7=G7,1,0) -> 0 | I7: =H7*INDEX(Question_Bank!$M$3:$M$14,MATCH(D7,Question_Bank!$A$3:$A$14,0)) -> 0 | J7: =SUMIFS($I$3:$I$518,$A$3:$A$518,A7) -> 0 | K7: =J7/SUM(Question_Bank!$M$3:$M$14) -> 0 | L7: =SUMIFS($I$3:$I$518,$A$3:$A$518,A7,$E$3:$E$518,E7)/SUMIFS(Question_Bank!$M$3:$M$14,Question_Bank!$B$3:$B$14,E7) -> 0 | M7: Zaid Khan
A8: SEM001 | B8: In-Person Seminar | C8: Pre | D8: Q06 | E8: Phishing | F8: D | G8: =INDEX(Question_Bank!$G$3:$G$14,MATCH(D8,Question_Bank!$A$3:$A$14,0)) -> 0 | H8: =IF(F8=G8,1,0) -> 0 | I8: =H8*INDEX(Question_Bank!$M$3:$M$14,MATCH(D8,Question_Bank!$A$3:$A$14,0)) -> 0 | J8: =SUMIFS($I$3:$I$518,$A$3:$A$518,A8) -> 0 | K8: =J8/SUM(Question_Bank!$M$3:$M$14) -> 0 | L8: =SUMIFS($I$3:$I$518,$A$3:$A$518,A8,$E$3:$E$518,E8)/SUMIFS(Question_Bank!$M$3:$M$14,Question_Bank!$B$3:$B$14,E8) -> 0 | M8: Zaid Khan
A9: SEM001 | B9: In-Person Seminar | C9: Pre | D9: Q07 | E9: Everyday Online Fraud | F9: D | G9: =INDEX(Question_Bank!$G$3:$G$14,MATCH(D9,Question_Bank!$A$3:$A$14,0)) -> 0 | H9: =IF(F9=G9,1,0) -> 0 | I9: =H9*INDEX(Question_Bank!$M$3:$M$14,MATCH(D9,Question_Bank!$A$3:$A$14,0)) -> 0 | J9: =SUMIFS($I$3:$I$518,$A$3:$A$518,A9) -> 0 | K9: =J9/SUM(Question_Bank!$M$3:$M$14) -> 0 | L9: =SUMIFS($I$3:$I$518,$A$3:$A$518,A9,$E$3:$E$518,E9)/SUMIFS(Question_Bank!$M$3:$M$14,Question_Bank!$B$3:$B$14,E9) -> 0 | M9: Zaid Khan
A10: SEM001 | B10: In-Person Seminar | C10: Pre | D10: Q08 | E10: Everyday Online Fraud | F10: C | G10: =INDEX(Question_Bank!$G$3:$G$14,MATCH(D10,Question_Bank!$A$3:$A$14,0)) -> 0 | H10: =IF(F10=G10,1,0) -> 0 | I10: =H10*INDEX(Question_Bank!$M$3:$M$14,MATCH(D10,Question_Bank!$A$3:$A$14,0)) -> 0 | J10: =SUMIFS($I$3:$I$518,$A$3:$A$518,A10) -> 0 | K10: =J10/SUM(Question_Bank!$M$3:$M$14) -> 0 | L10: =SUMIFS($I$3:$I$518,$A$3:$A$518,A10,$E$3:$E$518,E10)/SUMIFS(Question_Bank!$M$3:$M$14,Question_Bank!$B$3:$B$14,E10) -> 0 | M10: Zaid Khan
A11: SEM001 | B11: In-Person Seminar | C11: Pre | D11: Q09 | E11: Everyday Online Fraud | F11: C | G11: =INDEX(Question_Bank!$G$3:$G$14,MATCH(D11,Question_Bank!$A$3:$A$14,0)) -> 0 | H11: =IF(F11=G11,1,0) -> 0 | I11: =H11*INDEX(Question_Bank!$M$3:$M$14,MATCH(D11,Question_Bank!$A$3:$A$14,0)) -> 0 | J11: =SUMIFS($I$3:$I$518,$A$3:$A$518,A11) -> 0 | K11: =J11/SUM(Question_Bank!$M$3:$M$14) -> 0 | L11: =SUMIFS($I$3:$I$518,$A$3:$A$518,A11,$E$3:$E$518,E11)/SUMIFS(Question_Bank!$M$3:$M$14,Question_Bank!$B$3:$B$14,E11) -> 0 | M11: Zaid Khan
A12: SEM001 | B12: In-Person Seminar | C12: Pre | D12: Q10 | E12: Scam Prevention | F12: D | G12: =INDEX(Question_Bank!$G$3:$G$14,MATCH(D12,Question_Bank!$A$3:$A$14,0)) -> 0 | H12: =IF(F12=G12,1,0) -> 0 | I12: =H12*INDEX(Question_Bank!$M$3:$M$14,MATCH(D12,Question_Bank!$A$3:$A$14,0)) -> 0 | J12: =SUMIFS($I$3:$I$518,$A$3:$A$518,A12) -> 0 | K12: =J12/SUM(Question_Bank!$M$3:$M$14) -> 0 | L12: =SUMIFS($I$3:$I$518,$A$3:$A$518,A12,$E$3:$E$518,E12)/SUMIFS(Question_Bank!$M$3:$M$14,Question_Bank!$B$3:$B$14,E12) -> 0 | M12: Zaid Khan
A13: SEM001 | B13: In-Person Seminar | C13: Pre | D13: Q11 | E13: Scam Prevention | F13: A | G13: =INDEX(Question_Bank!$G$3:$G$14,MATCH(D13,Question_Bank!$A$3:$A$14,0)) -> 0 | H13: =IF(F13=G13,1,0) -> 0 | I13: =H13*INDEX(Question_Bank!$M$3:$M$14,MATCH(D13,Question_Bank!$A$3:$A$14,0)) -> 0 | J13: =SUMIFS($I$3:$I$518,$A$3:$A$518,A13) -> 0 | K13: =J13/SUM(Question_Bank!$M$3:$M$14) -> 0 | L13: =SUMIFS($I$3:$I$518,$A$3:$A$518,A13,$E$3:$E$518,E13)/SUMIFS(Question_Bank!$M$3:$M$14,Question_Bank!$B$3:$B$14,E13) -> 0 | M13: Zaid Khan
A14: SEM001 | B14: In-Person Seminar | C14: Pre | D14: Q12 | E14: Scam Prevention | F14: A | G14: =INDEX(Question_Bank!$G$3:$G$14,MATCH(D14,Question_Bank!$A$3:$A$14,0)) -> 0 | H14: =IF(F14=G14,1,0) -> 0 | I14: =H14*INDEX(Question_Bank!$M$3:$M$14,MATCH(D14,Question_Bank!$A$3:$A$14,0)) -> 0 | J14: =SUMIFS($I$3:$I$518,$A$3:$A$518,A14) -> 0 | K14: =J14/SUM(Question_Bank!$M$3:$M$14) -> 0 | L14: =SUMIFS($I$3:$I$518,$A$3:$A$518,A14,$E$3:$E$518,E14)/SUMIFS(Question_Bank!$M$3:$M$14,Question_Bank!$B$3:$B$14,E14) -> 0 | M14: Zaid Khan
... A518: SEM043 | B518: In-Person Seminar | C518: Pre | D518: Q12 | E518: Scam Prevention | F518: B | G518: =INDEX(Question_Bank!$G$3:$G$14,MATCH(D518,Question_Bank!$A$3:$A$14,0)) -> 0 | H518: =IF(F518=G518,1,0) -> 0 | I518: =H518*INDEX(Question_Bank!$M$3:$M$14,MATCH(D518,Question_Bank!$A$3:$A$14,0)) -> 0 | J518: =SUMIFS($I$3:$I$518,$A$3:$A$518,A518) -> 0 | K518: =J518/SUM(Question_Bank!$M$3:$M$14) -> 0 | L518: =SUMIFS($I$3:$I$518,$A$3:$A$518,A518,$E$3:$E$518,E518)/SUMIFS(Question_Bank!$M$3:$M$14,Question_Bank!$B$3:$B$14,E518) -> 0 | M518: Simran Srivastava

Sheet Seminar_Post
A1: Scam Shield - cybersecurity awareness impact evaluation
A2: Participant_ID | B2: Intervention_Group | C2: Assessment_Stage | D2: Question_ID | E2: Topic | F2: Selected_Answer | G2: Correct_Answer | H2: Is_Correct | I2: Question_Score | J2: Overall_Score | K2: Overall_Pct | L2: Topic_Accuracy | M2: Participant_Name
A3: SEM001 | B3: In-Person Seminar | C3: Post | D3: Q01 | E3: WhatsApp Scams | F3: C | G3: =INDEX(Question_Bank!$J$3:$J$14,MATCH(D3,Question_Bank!$A$3:$A$14,0)) -> 0 | H3: =IF(F3=G3,1,0) -> 0 | I3: =H3*INDEX(Question_Bank!$M$3:$M$14,MATCH(D3,Question_Bank!$A$3:$A$14,0)) -> 0 | J3: =SUMIFS($I$3:$I$518,$A$3:$A$518,A3) -> 0 | K3: =J3/SUM(Question_Bank!$M$3:$M$14) -> 0 | L3: =SUMIFS($I$3:$I$518,$A$3:$A$518,A3,$E$3:$E$518,E3)/SUMIFS(Question_Bank!$M$3:$M$14,Question_Bank!$B$3:$B$14,E3) -> 0 | M3: Zaid Khan
A4: SEM001 | B4: In-Person Seminar | C4: Post | D4: Q02 | E4: WhatsApp Scams | F4: D | G4: =INDEX(Question_Bank!$J$3:$J$14,MATCH(D4,Question_Bank!$A$3:$A$14,0)) -> 0 | H4: =IF(F4=G4,1,0) -> 0 | I4: =H4*INDEX(Question_Bank!$M$3:$M$14,MATCH(D4,Question_Bank!$A$3:$A$14,0)) -> 0 | J4: =SUMIFS($I$3:$I$518,$A$3:$A$518,A4) -> 0 | K4: =J4/SUM(Question_Bank!$M$3:$M$14) -> 0 | L4: =SUMIFS($I$3:$I$518,$A$3:$A$518,A4,$E$3:$E$518,E4)/SUMIFS(Question_Bank!$M$3:$M$14,Question_Bank!$B$3:$B$14,E4) -> 0 | M4: Zaid Khan
A5: SEM001 | B5: In-Person Seminar | C5: Post | D5: Q03 | E5: WhatsApp Scams | F5: A | G5: =INDEX(Question_Bank!$J$3:$J$14,MATCH(D5,Question_Bank!$A$3:$A$14,0)) -> 0 | H5: =IF(F5=G5,1,0) -> 0 | I5: =H5*INDEX(Question_Bank!$M$3:$M$14,MATCH(D5,Question_Bank!$A$3:$A$14,0)) -> 0 | J5: =SUMIFS($I$3:$I$518,$A$3:$A$518,A5) -> 0 | K5: =J5/SUM(Question_Bank!$M$3:$M$14) -> 0 | L5: =SUMIFS($I$3:$I$518,$A$3:$A$518,A5,$E$3:$E$518,E5)/SUMIFS(Question_Bank!$M$3:$M$14,Question_Bank!$B$3:$B$14,E5) -> 0 | M5: Zaid Khan
A6: SEM001 | B6: In-Person Seminar | C6: Post | D6: Q04 | E6: Phishing | F6: B | G6: =INDEX(Question_Bank!$J$3:$J$14,MATCH(D6,Question_Bank!$A$3:$A$14,0)) -> 0 | H6: =IF(F6=G6,1,0) -> 0 | I6: =H6*INDEX(Question_Bank!$M$3:$M$14,MATCH(D6,Question_Bank!$A$3:$A$14,0)) -> 0 | J6: =SUMIFS($I$3:$I$518,$A$3:$A$518,A6) -> 0 | K6: =J6/SUM(Question_Bank!$M$3:$M$14) -> 0 | L6: =SUMIFS($I$3:$I$518,$A$3:$A$518,A6,$E$3:$E$518,E6)/SUMIFS(Question_Bank!$M$3:$M$14,Question_Bank!$B$3:$B$14,E6) -> 0 | M6: Zaid Khan
A7: SEM001 | B7: In-Person Seminar | C7: Post | D7: Q05 | E7: Phishing | F7: C | G7: =INDEX(Question_Bank!$J$3:$J$14,MATCH(D7,Question_Bank!$A$3:$A$14,0)) -> 0 | H7: =IF(F7=G7,1,0) -> 0 | I7: =H7*INDEX(Question_Bank!$M$3:$M$14,MATCH(D7,Question_Bank!$A$3:$A$14,0)) -> 0 | J7: =SUMIFS($I$3:$I$518,$A$3:$A$518,A7) -> 0 | K7: =J7/SUM(Question_Bank!$M$3:$M$14) -> 0 | L7: =SUMIFS($I$3:$I$518,$A$3:$A$518,A7,$E$3:$E$518,E7)/SUMIFS(Question_Bank!$M$3:$M$14,Question_Bank!$B$3:$B$14,E7) -> 0 | M7: Zaid Khan
A8: SEM001 | B8: In-Person Seminar | C8: Post | D8: Q06 | E8: Phishing | F8: D | G8: =INDEX(Question_Bank!$J$3:$J$14,MATCH(D8,Question_Bank!$A$3:$A$14,0)) -> 0 | H8: =IF(F8=G8,1,0) -> 0 | I8: =H8*INDEX(Question_Bank!$M$3:$M$14,MATCH(D8,Question_Bank!$A$3:$A$14,0)) -> 0 | J8: =SUMIFS($I$3:$I$518,$A$3:$A$518,A8) -> 0 | K8: =J8/SUM(Question_Bank!$M$3:$M$14) -> 0 | L8: =SUMIFS($I$3:$I$518,$A$3:$A$518,A8,$E$3:$E$518,E8)/SUMIFS(Question_Bank!$M$3:$M$14,Question_Bank!$B$3:$B$14,E8) -> 0 | M8: Zaid Khan
A9: SEM001 | B9: In-Person Seminar | C9: Post | D9: Q07 | E9: Everyday Online Fraud | F9: A | G9: =INDEX(Question_Bank!$J$3:$J$14,MATCH(D9,Question_Bank!$A$3:$A$14,0)) -> 0 | H9: =IF(F9=G9,1,0) -> 0 | I9: =H9*INDEX(Question_Bank!$M$3:$M$14,MATCH(D9,Question_Bank!$A$3:$A$14,0)) -> 0 | J9: =SUMIFS($I$3:$I$518,$A$3:$A$518,A9) -> 0 | K9: =J9/SUM(Question_Bank!$M$3:$M$14) -> 0 | L9: =SUMIFS($I$3:$I$518,$A$3:$A$518,A9,$E$3:$E$518,E9)/SUMIFS(Question_Bank!$M$3:$M$14,Question_Bank!$B$3:$B$14,E9) -> 0 | M9: Zaid Khan
A10: SEM001 | B10: In-Person Seminar | C10: Post | D10: Q08 | E10: Everyday Online Fraud | F10: A | G10: =INDEX(Question_Bank!$J$3:$J$14,MATCH(D10,Question_Bank!$A$3:$A$14,0)) -> 0 | H10: =IF(F10=G10,1,0) -> 0 | I10: =H10*INDEX(Question_Bank!$M$3:$M$14,MATCH(D10,Question_Bank!$A$3:$A$14,0)) -> 0 | J10: =SUMIFS($I$3:$I$518,$A$3:$A$518,A10) -> 0 | K10: =J10/SUM(Question_Bank!$M$3:$M$14) -> 0 | L10: =SUMIFS($I$3:$I$518,$A$3:$A$518,A10,$E$3:$E$518,E10)/SUMIFS(Question_Bank!$M$3:$M$14,Question_Bank!$B$3:$B$14,E10) -> 0 | M10: Zaid Khan
A11: SEM001 | B11: In-Person Seminar | C11: Post | D11: Q09 | E11: Everyday Online Fraud | F11: C | G11: =INDEX(Question_Bank!$J$3:$J$14,MATCH(D11,Question_Bank!$A$3:$A$14,0)) -> 0 | H11: =IF(F11=G11,1,0) -> 0 | I11: =H11*INDEX(Question_Bank!$M$3:$M$14,MATCH(D11,Question_Bank!$A$3:$A$14,0)) -> 0 | J11: =SUMIFS($I$3:$I$518,$A$3:$A$518,A11) -> 0 | K11: =J11/SUM(Question_Bank!$M$3:$M$14) -> 0 | L11: =SUMIFS($I$3:$I$518,$A$3:$A$518,A11,$E$3:$E$518,E11)/SUMIFS(Question_Bank!$M$3:$M$14,Question_Bank!$B$3:$B$14,E11) -> 0 | M11: Zaid Khan
A12: SEM001 | B12: In-Person Seminar | C12: Post | D12: Q10 | E12: Scam Prevention | F12: D | G12: =INDEX(Question_Bank!$J$3:$J$14,MATCH(D12,Question_Bank!$A$3:$A$14,0)) -> 0 | H12: =IF(F12=G12,1,0) -> 0 | I12: =H12*INDEX(Question_Bank!$M$3:$M$14,MATCH(D12,Question_Bank!$A$3:$A$14,0)) -> 0 | J12: =SUMIFS($I$3:$I$518,$A$3:$A$518,A12) -> 0 | K12: =J12/SUM(Question_Bank!$M$3:$M$14) -> 0 | L12: =SUMIFS($I$3:$I$518,$A$3:$A$518,A12,$E$3:$E$518,E12)/SUMIFS(Question_Bank!$M$3:$M$14,Question_Bank!$B$3:$B$14,E12) -> 0 | M12: Zaid Khan
A13: SEM001 | B13: In-Person Seminar | C13: Post | D13: Q11 | E13: Scam Prevention | F13: A | G13: =INDEX(Question_Bank!$J$3:$J$14,MATCH(D13,Question_Bank!$A$3:$A$14,0)) -> 0 | H13: =IF(F13=G13,1,0) -> 0 | I13: =H13*INDEX(Question_Bank!$M$3:$M$14,MATCH(D13,Question_Bank!$A$3:$A$14,0)) -> 0 | J13: =SUMIFS($I$3:$I$518,$A$3:$A$518,A13) -> 0 | K13: =J13/SUM(Question_Bank!$M$3:$M$14) -> 0 | L13: =SUMIFS($I$3:$I$518,$A$3:$A$518,A13,$E$3:$E$518,E13)/SUMIFS(Question_Bank!$M$3:$M$14,Question_Bank!$B$3:$B$14,E13) -> 0 | M13: Zaid Khan
A14: SEM001 | B14: In-Person Seminar | C14: Post | D14: Q12 | E14: Scam Prevention | F14: A | G14: =INDEX(Question_Bank!$J$3:$J$14,MATCH(D14,Question_Bank!$A$3:$A$14,0)) -> 0 | H14: =IF(F14=G14,1,0) -> 0 | I14: =H14*INDEX(Question_Bank!$M$3:$M$14,MATCH(D14,Question_Bank!$A$3:$A$14,0)) -> 0 | J14: =SUMIFS($I$3:$I$518,$A$3:$A$518,A14) -> 0 | K14: =J14/SUM(Question_Bank!$M$3:$M$14) -> 0 | L14: =SUMIFS($I$3:$I$518,$A$3:$A$518,A14,$E$3:$E$518,E14)/SUMIFS(Question_Bank!$M$3:$M$14,Question_Bank!$B$3:$B$14,E14) -> 0 | M14: Zaid Khan
... A518: SEM043 | B518: In-Person Seminar | C518: Post | D518: Q12 | E518: Scam Prevention | F518: B | G518: =INDEX(Question_Bank!$J$3:$J$14,MATCH(D518,Question_Bank!$A$3:$A$14,0)) -> 0 | H518: =IF(F518=G518,1,0) -> 0 | I518: =H518*INDEX(Question_Bank!$M$3:$M$14,MATCH(D518,Question_Bank!$A$3:$A$14,0)) -> 0 | J518: =SUMIFS($I$3:$I$518,$A$3:$A$518,A518) -> 0 | K518: =J518/SUM(Question_Bank!$M$3:$M$14) -> 0 | L518: =SUMIFS($I$3:$I$518,$A$3:$A$518,A518,$E$3:$E$518,E518)/SUMIFS(Question_Bank!$M$3:$M$14,Question_Bank!$B$3:$B$14,E518) -> 0 | M518: Simran Srivastava

Sheet Question_Bank
A1: Scam Shield - cybersecurity awareness impact evaluation
A2: Question_ID | B2: Topic | C2: Objective | D2: Type | E2: Pre_Question | F2: Pre_Options | G2: Pre_Correct | H2: Post_Question | I2: Post_Options | J2: Post_Correct | K2: Explanation_Pre | L2: Explanation_Post | M2: Points
A3: Q01 | B3: WhatsApp Scams | C3: Impersonation of family or boss | D3: scenario | E3: "Hi Mum, I dropped my phone, this is my new number. Please pay this bill urgently, I'll explain later." The profile photo is your child's. What first? | F3: A) Call your child on their old, saved number to confirm B) Send the money, it's an emergency C) Ask them to send a selfie D) Reply asking them to share the bank details | G3: A | H3: Your 'manager' messages from an unsaved number: "In a meeting, can't talk. Buy 5 gift cards for a client and send me the codes." What do you do? | I3: A) Buy them, then confirm later B) Ask for the codes to be sent to a company email first C) Verify with your manager via a known number or in person before doing anything D) Buy just one card to be safe | J3: C | K3: Scammers copy public photos. Confirm through a channel you already trust, like the old number, before sending anything. | L3: Boss impersonation relies on secrecy and urgency. Gift-card codes are untraceable, so verify first through a trusted channel. | M3: 1
A4: Q02 | B4: WhatsApp Scams | C4: Account takeover via verification code | D4: mcq | E4: A friend's WhatsApp asks: "I sent you a 6-digit code by mistake, please forward it to me." What is this? | F4: A) A harmless mix-up, forward the code B) An attempt to take over your WhatsApp account C) A bug in WhatsApp D) A way to verify the friend's identity | G4: B | H4: You receive an unexpected WhatsApp verification SMS, then a contact messages: "Sorry, wrong number, can you read me the code?" What should you do? | I4: A) Read it out, it's polite B) Share it but change your password afterwards C) Reply with only the last 3 digits D) Never share it, and tell the contact to use another route | J4: D | K4: That code is your own WhatsApp login code. Anyone holding it can register your number on their device. | L4: Verification codes must never be shared, in full or in part. A contact asking is likely already compromised. | M4: 1
A5: Q03 | B5: WhatsApp Scams | C5: Fraudulent investment groups | D5: scenario | E5: You're added to a WhatsApp group where members post screenshots of daily stock profits and an 'expert' urges you to install an app to join an IPO quota. What's the smartest move? | F5: A) Join with a small amount B) Ask the expert for their experience C) Leave the group, don't install the app, and report it D) Wait to see if members really profit | G5: C | H5: A 'crypto signals' group promises guaranteed 3x returns in 30 days if you deposit through their platform. Which fact most clearly marks this as a scam? | I5: A) Guaranteed high returns B) The group has many members C) The admin is friendly D) Payments are made online | J5: A | K5: Fake members and fabricated screenshots create social proof. Unregistered apps let scammers show fake gains while taking your deposits. | L5: No legitimate investment can guarantee high returns. Guarantees, pressure and pooled unregulated platforms signal fraud. | M5: 1
A6: Q04 | B6: Phishing | C6: Spotting a genuine URL | D6: mcq | E6: Which of these is most likely the genuine Amazon India website? | F6: A) amazon-in-support.com B) amazon.in.secure-login.net C) arnazon.in D) amazon.in | G6: D | H6: Which URL is most likely the genuine Flipkart site? | I6: A) flipkart-offers.shop B) flipkart.com C) flipkart.com.deals-today.in D) fIipkart.com | J6: B | K6: Read the domain from right to left up to the first slash. The brand must be the registered domain, and lookalikes like 'arnazon' swap characters. | L6: Extra words, odd endings or subdomain tricks can hide a fake registered domain. Stick to the exact brand domain. | M6: 1
A7: Q05 | B7: Phishing | C7: QR-code phishing (quishing) | D7: scenario | E7: At a café you notice the payment QR code is a sticker placed over the original one. What should you do? | F7: A) Ask the staff to confirm and check the merchant name shown before paying B) Scan it, since it's the café's code C) Pay a small test amount D) Scan it with a different app | G7: A | H7: An email says: "Scan the QR code to re-enable your account's two-factor authentication." What do you do? | I7: A) Scan with your phone's camera B) Scan but don't log in C) Don't scan, and check settings in the official app instead D) Print it and scan on another phone | J7: C | K7: Scammers paste their own QR codes over genuine ones. Confirm with staff and check the payee name before paying. | L7: QR codes hide the destination from email filters and from you. Make security changes only inside the official app or site. | M7: 1
A8: Q06 | B8: Phishing | C8: OTP theft by phone | D8: scenario | E8: A caller says: "I'm from your bank. A ₹40,000 transaction is pending, share the OTP now to cancel it." What is the correct response? | F8: A) Share the OTP to cancel the transaction B) Hang up and call the number on your card or bank's official site C) Share only 3 digits D) Ask the caller for their employee ID | G8: B | H8: A 'delivery agent' calls and asks you to read out the OTP you just received 'to confirm the delivery'. You aren't sure what order it's for. What do you do? | I8: A) Read it out B) Read it out after verifying the agent's name C) Ask them to send it as a text D) Refuse, since OTPs are never needed to receive a parcel | J8: D | K8: An OTP authorises a payment, it never cancels one. Banks never ask for OTPs. Calling back via official numbers verifies the claim. | L8: Genuine OTP-based delivery codes are rare and tied to your order. If you can't tell, treat it as theft and don't share. | M8: 1
A9: Q07 | B9: Everyday Online Fraud | C9: UPI collect request fraud | D9: scenario | E9: You're selling a sofa online. The buyer says: "I've sent you the money, approve the request on your UPI app and enter your PIN to receive it." What's wrong? | F9: A) Nothing, that's how UPI works B) The buyer used the wrong app C) Entering a PIN sends money out, receiving money never needs a PIN D) The request has expired | G9: C | H9: A seller says they've sent you a refund via a UPI 'request'. You see a prompt asking you to enter your UPI PIN. What do you do? | I9: A) Decline the request and don't enter your PIN B) Enter the PIN to get the refund C) Enter the PIN but check the amount first D) Ask the seller to try again | J9: A | K9: You never enter a UPI PIN to receive money. A collect request with a PIN prompt is pulling money out of your account. | L9: Refunds are credited automatically. A PIN prompt means money is leaving your account. | M9: 1
A10: Q08 | B10: Everyday Online Fraud | C10: Screen-sharing and remote-access scams | D10: scenario | E10: A 'support executive' asks you to install AnyDesk so they can 'fix your refund'. What happens if you do? | F10: A) Nothing, it's only a chat tool B) They can only see your photos C) It just checks your internet speed D) They can see and control your phone, including banking apps | G10: D | H10: A caller claiming to be from your telecom provider says KYC has expired and asks you to share your screen via a quick-support app. Best action? | I10: A) Share the screen but not the OTP B) Decline, and visit the operator's store or official app C) Share the screen while on loudspeaker D) Share only for a minute | J10: B | K10: Remote-access tools let scammers watch your screen, see OTPs and move money themselves. | L10: No legitimate service needs remote control of your phone for KYC. Visit the official store or app instead. | M10: 1
A11: Q09 | B11: Everyday Online Fraud | C11: Digital arrest scams | D11: scenario | E11: On a video call, a person in uniform says a parcel in your name contains illegal items, that you're under 'digital arrest', and must stay on camera and transfer money for 'verification'. What is this? | F11: A) A scam: no agency arrests or investigates people by video call and demands money B) A real police process C) A court notice D) A routine bank check | G11: A | H11: A caller says they're from TRAI and your number will be disconnected for illegal activity, then connects you to a 'police officer' who tells you not to tell anyone and to move your savings 'for safety'. What do you do? | I11: A) Follow instructions, to avoid arrest B) Move only part of your money C) Hang up, tell family, and report at 1930 or cybercrime.gov.in D) Ask them to send a letter by post | J11: C | K11: 'Digital arrest' doesn't exist in law. Agencies don't demand payments or isolation over a call. Disconnect and report to 1930. | L11: Secrecy and pressure are core scam tactics. Real authorities don't ask you to transfer money to prove innocence. | M11: 1
A12: Q10 | B12: Scam Prevention | C12: Recognising warning signs | D12: mcq | E12: Which combination of signs most strongly suggests a scam? | F12: A) A greeting and a company logo B) Urgency, secrecy and a request for money or codes C) A message sent late at night D) A message with a typo | G12: B | H12: Which of these should make you most suspicious of a message? | I12: A) It comes from a contact you've saved B) It includes your first name C) It has a link to a well-known brand D) It offers a prize and says 'claim in the next 10 minutes, don't tell anyone' | J12: D | K12: Pressure to act fast, keep quiet and hand over money or codes is the common thread across scam types. | L12: Time pressure and secrecy stop you from checking with others. Slow down and verify. | M12: 1
A13: Q11 | B13: Scam Prevention | C13: Verifying identity through a second channel | D13: scenario | E13: A relative's WhatsApp account messages you asking for urgent money. What is the most reliable way to check? | F13: A) Ask a personal question in the same chat B) Check their profile photo C) Call them on a number you already know D) Ask them to send a voice note | G13: C | H13: A caller says they're from your bank. How do you confirm it? | I13: A) Hang up and dial the number printed on your card or the bank's website B) Trust the caller ID on your screen C) Ask the caller to verify your details D) Ask them to call back in an hour | J13: A | K13: If the account is hijacked, everything in that chat is controlled by the scammer. Use a separate, trusted channel. | L13: Caller ID can be faked. Call the official number yourself to reach the real bank. | M13: 1
A14: Q12 | B14: Scam Prevention | C14: Reporting and responding safely | D14: mcq | E14: You've just lost money in an online scam. What is the best first step? | F14: A) Wait a week to see if it's refunded B) Post about it and wait for replies C) Message the scammer to ask for a refund D) Call the national cybercrime helpline 1930 and report at cybercrime.gov.in quickly | G14: D | H14: You realise you shared your OTP with a fraudster and money has left your account. What do you do first? | I14: A) Wait for the bank to notice B) Contact your bank to block the account or card, and report to 1930 C) Delete the chat D) Change your phone wallpaper | J14: B | K14: Fast reporting improves the chance of freezing funds. The helpline is 1930 and complaints are filed at cybercrime.gov.in. | L14: Speed is critical. Alert your bank so it can block transactions, and report to the cybercrime helpline. | M14: 1

Sheet Social_Analysis
A1: Social Media Campaign analysis - Scam Shield - cybersecurity awareness impact evaluation
A3: Metric | B3: Value | H3: Participant_ID | I3: Pre_Score | J3: Post_Score | K3: Pre_Pct | L3: Post_Pct | M3: Change_Points | N3: Change_pp | O3: Category | P3: Participant_Name
A4: Matched participants | B4: =COUNTA($H$4:$H$50) -> 0 | H4: SM001 | I4: =SUMIFS(Social_Pre!$I$3:$I$566,Social_Pre!$A$3:$A$566,H4) -> 0 | J4: =SUMIFS(Social_Post!$I$3:$I$566,Social_Post!$A$3:$A$566,H4) -> 0 | K4: =I4/SUM(Question_Bank!$M$3:$M$14) -> 0 | L4: =J4/SUM(Question_Bank!$M$3:$M$14) -> 0 | M4: =J4-I4 -> 0 | N4: =(L4-K4)*100 -> 0 | O4: =IF(M4>=$B$23,"Substantial",IF(M4>=$B$24,"Modest",IF(M4=0,"Unchanged","Lower"))) -> 0 | P4: Zaid Bhatia
A5: Average pre score (points) | B5: =AVERAGE($I$4:$I$50) -> 0 | H5: SM002 | I5: =SUMIFS(Social_Pre!$I$3:$I$566,Social_Pre!$A$3:$A$566,H5) -> 0 | J5: =SUMIFS(Social_Post!$I$3:$I$566,Social_Post!$A$3:$A$566,H5) -> 0 | K5: =I5/SUM(Question_Bank!$M$3:$M$14) -> 0 | L5: =J5/SUM(Question_Bank!$M$3:$M$14) -> 0 | M5: =J5-I5 -> 0 | N5: =(L5-K5)*100 -> 0 | O5: =IF(M5>=$B$23,"Substantial",IF(M5>=$B$24,"Modest",IF(M5=0,"Unchanged","Lower"))) -> 0 | P5: Aishwarya Choudhary
A6: Average post score (points) | B6: =AVERAGE($J$4:$J$50) -> 0 | H6: SM003 | I6: =SUMIFS(Social_Pre!$I$3:$I$566,Social_Pre!$A$3:$A$566,H6) -> 0 | J6: =SUMIFS(Social_Post!$I$3:$I$566,Social_Post!$A$3:$A$566,H6) -> 0 | K6: =I6/SUM(Question_Bank!$M$3:$M$14) -> 0 | L6: =J6/SUM(Question_Bank!$M$3:$M$14) -> 0 | M6: =J6-I6 -> 0 | N6: =(L6-K6)*100 -> 0 | O6: =IF(M6>=$B$23,"Substantial",IF(M6>=$B$24,"Modest",IF(M6=0,"Unchanged","Lower"))) -> 0 | P6: Aditya Kapoor
A7: Average pre score (%) | B7: =AVERAGE($K$4:$K$50) -> 0 | H7: SM004 | I7: =SUMIFS(Social_Pre!$I$3:$I$566,Social_Pre!$A$3:$A$566,H7) -> 0 | J7: =SUMIFS(Social_Post!$I$3:$I$566,Social_Post!$A$3:$A$566,H7) -> 0 | K7: =I7/SUM(Question_Bank!$M$3:$M$14) -> 0 | L7: =J7/SUM(Question_Bank!$M$3:$M$14) -> 0 | M7: =J7-I7 -> 0 | N7: =(L7-K7)*100 -> 0 | O7: =IF(M7>=$B$23,"Substantial",IF(M7>=$B$24,"Modest",IF(M7=0,"Unchanged","Lower"))) -> 0 | P7: Sandeep Pillai
A8: Average post score (%) | B8: =AVERAGE($L$4:$L$50) -> 0 | H8: SM005 | I8: =SUMIFS(Social_Pre!$I$3:$I$566,Social_Pre!$A$3:$A$566,H8) -> 0 | J8: =SUMIFS(Social_Post!$I$3:$I$566,Social_Post!$A$3:$A$566,H8) -> 0 | K8: =I8/SUM(Question_Bank!$M$3:$M$14) -> 0 | L8: =J8/SUM(Question_Bank!$M$3:$M$14) -> 0 | M8: =J8-I8 -> 0 | N8: =(L8-K8)*100 -> 0 | O8: =IF(M8>=$B$23,"Substantial",IF(M8>=$B$24,"Modest",IF(M8=0,"Unchanged","Lower"))) -> 0 | P8: Aditya Bhat
A9: Absolute improvement (percentage points) | B9: =(B8-B7)*100 -> 0 | H9: SM006 | I9: =SUMIFS(Social_Pre!$I$3:$I$566,Social_Pre!$A$3:$A$566,H9) -> 0 | J9: =SUMIFS(Social_Post!$I$3:$I$566,Social_Post!$A$3:$A$566,H9) -> 0 | K9: =I9/SUM(Question_Bank!$M$3:$M$14) -> 0 | L9: =J9/SUM(Question_Bank!$M$3:$M$14) -> 0 | M9: =J9-I9 -> 0 | N9: =(L9-K9)*100 -> 0 | O9: =IF(M9>=$B$23,"Substantial",IF(M9>=$B$24,"Modest",IF(M9=0,"Unchanged","Lower"))) -> 0 | P9: Ishaan Singh
A10: Relative improvement (% of baseline) | B10: =(B8-B7)/B7 -> 0 | H10: SM007 | I10: =SUMIFS(Social_Pre!$I$3:$I$566,Social_Pre!$A$3:$A$566,H10) -> 0 | J10: =SUMIFS(Social_Post!$I$3:$I$566,Social_Post!$A$3:$A$566,H10) -> 0 | K10: =I10/SUM(Question_Bank!$M$3:$M$14) -> 0 | L10: =J10/SUM(Question_Bank!$M$3:$M$14) -> 0 | M10: =J10-I10 -> 0 | N10: =(L10-K10)*100 -> 0 | O10: =IF(M10>=$B$23,"Substantial",IF(M10>=$B$24,"Modest",IF(M10=0,"Unchanged","Lower"))) -> 0 | P10: Shruti Choudhary
A11: Participants whose score increased | B11: =COUNTIF($M$4:$M$50,">0")/B4 -> 0 | H11: SM008 | I11: =SUMIFS(Social_Pre!$I$3:$I$566,Social_Pre!$A$3:$A$566,H11) -> 0 | J11: =SUMIFS(Social_Post!$I$3:$I$566,Social_Post!$A$3:$A$566,H11) -> 0 | K11: =I11/SUM(Question_Bank!$M$3:$M$14) -> 0 | L11: =J11/SUM(Question_Bank!$M$3:$M$14) -> 0 | M11: =J11-I11 -> 0 | N11: =(L11-K11)*100 -> 0 | O11: =IF(M11>=$B$23,"Substantial",IF(M11>=$B$24,"Modest",IF(M11=0,"Unchanged","Lower"))) -> 0 | P11: Mahima Srivastava
A12: Mean score change (points) | B12: =AVERAGE($M$4:$M$50) -> 0 | H12: SM009 | I12: =SUMIFS(Social_Pre!$I$3:$I$566,Social_Pre!$A$3:$A$566,H12) -> 0 | J12: =SUMIFS(Social_Post!$I$3:$I$566,Social_Post!$A$3:$A$566,H12) -> 0 | K12: =I12/SUM(Question_Bank!$M$3:$M$14) -> 0 | L12: =J12/SUM(Question_Bank!$M$3:$M$14) -> 0 | M12: =J12-I12 -> 0 | N12: =(L12-K12)*100 -> 0 | O12: =IF(M12>=$B$23,"Substantial",IF(M12>=$B$24,"Modest",IF(M12=0,"Unchanged","Lower"))) -> 0 | P12: Farah Kapoor
A13: Post-accuracy target (flag below) | B13: 0.6 | H13: SM010 | I13: =SUMIFS(Social_Pre!$I$3:$I$566,Social_Pre!$A$3:$A$566,H13) -> 0 | J13: =SUMIFS(Social_Post!$I$3:$I$566,Social_Post!$A$3:$A$566,H13) -> 0 | K13: =I13/SUM(Question_Bank!$M$3:$M$14) -> 0 | L13: =J13/SUM(Question_Bank!$M$3:$M$14) -> 0 | M13: =J13-I13 -> 0 | N13: =(L13-K13)*100 -> 0 | O13: =IF(M13>=$B$23,"Substantial",IF(M13>=$B$24,"Modest",IF(M13=0,"Unchanged","Lower"))) -> 0 | P13: Neha Singh
H14: SM011 | I14: =SUMIFS(Social_Pre!$I$3:$I$566,Social_Pre!$A$3:$A$566,H14) -> 0 | J14: =SUMIFS(Social_Post!$I$3:$I$566,Social_Post!$A$3:$A$566,H14) -> 0 | K14: =I14/SUM(Question_Bank!$M$3:$M$14) -> 0 | L14: =J14/SUM(Question_Bank!$M$3:$M$14) -> 0 | M14: =J14-I14 -> 0 | N14: =(L14-K14)*100 -> 0 | O14: =IF(M14>=$B$23,"Substantial",IF(M14>=$B$24,"Modest",IF(M14=0,"Unchanged","Lower"))) -> 0 | P14: Nandini Sharma
A15: Topic | B15: Pre accuracy | C15: Post accuracy | D15: Change (pp) | E15: Flag | H15: SM012 | I15: =SUMIFS(Social_Pre!$I$3:$I$566,Social_Pre!$A$3:$A$566,H15) -> 0 | J15: =SUMIFS(Social_Post!$I$3:$I$566,Social_Post!$A$3:$A$566,H15) -> 0 | K15: =I15/SUM(Question_Bank!$M$3:$M$14) -> 0 | L15: =J15/SUM(Question_Bank!$M$3:$M$14) -> 0 | M15: =J15-I15 -> 0 | N15: =(L15-K15)*100 -> 0 | O15: =IF(M15>=$B$23,"Substantial",IF(M15>=$B$24,"Modest",IF(M15=0,"Unchanged","Lower"))) -> 0 | P15: Simran Srivastava
A16: WhatsApp Scams | B16: =SUMIFS(Social_Pre!$H$3:$H$566,Social_Pre!$E$3:$E$566,$A16)/COUNTIFS(Social_Pre!$E$3:$E$566,$A16) -> 0 | C16: =SUMIFS(Social_Post!$H$3:$H$566,Social_Post!$E$3:$E$566,$A16)/COUNTIFS(Social_Post!$E$3:$E$566,$A16) -> 0 | D16: =(C16-B16)*100 -> 0 | E16: =IF(C16<$B$13,"Needs further education","") -> 0 | H16: SM013 | I16: =SUMIFS(Social_Pre!$I$3:$I$566,Social_Pre!$A$3:$A$566,H16) -> 0 | J16: =SUMIFS(Social_Post!$I$3:$I$566,Social_Post!$A$3:$A$566,H16) -> 0 | K16: =I16/SUM(Question_Bank!$M$3:$M$14) -> 0 | L16: =J16/SUM(Question_Bank!$M$3:$M$14) -> 0 | M16: =J16-I16 -> 0 | N16: =(L16-K16)*100 -> 0 | O16: =IF(M16>=$B$23,"Substantial",IF(M16>=$B$24,"Modest",IF(M16=0,"Unchanged","Lower"))) -> 0 | P16: Ritika Saxena
A17: Phishing | B17: =SUMIFS(Social_Pre!$H$3:$H$566,Social_Pre!$E$3:$E$566,$A17)/COUNTIFS(Social_Pre!$E$3:$E$566,$A17) -> 0 | C17: =SUMIFS(Social_Post!$H$3:$H$566,Social_Post!$E$3:$E$566,$A17)/COUNTIFS(Social_Post!$E$3:$E$566,$A17) -> 0 | D17: =(C17-B17)*100 -> 0 | E17: =IF(C17<$B$13,"Needs further education","") -> 0 | H17: SM014 | I17: =SUMIFS(Social_Pre!$I$3:$I$566,Social_Pre!$A$3:$A$566,H17) -> 0 | J17: =SUMIFS(Social_Post!$I$3:$I$566,Social_Post!$A$3:$A$566,H17) -> 0 | K17: =I17/SUM(Question_Bank!$M$3:$M$14) -> 0 | L17: =J17/SUM(Question_Bank!$M$3:$M$14) -> 0 | M17: =J17-I17 -> 0 | N17: =(L17-K17)*100 -> 0 | O17: =IF(M17>=$B$23,"Substantial",IF(M17>=$B$24,"Modest",IF(M17=0,"Unchanged","Lower"))) -> 0 | P17: Dev Banerjee
A18: Everyday Online Fraud | B18: =SUMIFS(Social_Pre!$H$3:$H$566,Social_Pre!$E$3:$E$566,$A18)/COUNTIFS(Social_Pre!$E$3:$E$566,$A18) -> 0 | C18: =SUMIFS(Social_Post!$H$3:$H$566,Social_Post!$E$3:$E$566,$A18)/COUNTIFS(Social_Post!$E$3:$E$566,$A18) -> 0 | D18: =(C18-B18)*100 -> 0 | E18: =IF(C18<$B$13,"Needs further education","") -> 0 | H18: SM015 | I18: =SUMIFS(Social_Pre!$I$3:$I$566,Social_Pre!$A$3:$A$566,H18) -> 0 | J18: =SUMIFS(Social_Post!$I$3:$I$566,Social_Post!$A$3:$A$566,H18) -> 0 | K18: =I18/SUM(Question_Bank!$M$3:$M$14) -> 0 | L18: =J18/SUM(Question_Bank!$M$3:$M$14) -> 0 | M18: =J18-I18 -> 0 | N18: =(L18-K18)*100 -> 0 | O18: =IF(M18>=$B$23,"Substantial",IF(M18>=$B$24,"Modest",IF(M18=0,"Unchanged","Lower"))) -> 0 | P18: Simran Yadav
A19: Scam Prevention | B19: =SUMIFS(Social_Pre!$H$3:$H$566,Social_Pre!$E$3:$E$566,$A19)/COUNTIFS(Social_Pre!$E$3:$E$566,$A19) -> 0 | C19: =SUMIFS(Social_Post!$H$3:$H$566,Social_Post!$E$3:$E$566,$A19)/COUNTIFS(Social_Post!$E$3:$E$566,$A19) -> 0 | D19: =(C19-B19)*100 -> 0 | E19: =IF(C19<$B$13,"Needs further education","") -> 0 | H19: SM016 | I19: =SUMIFS(Social_Pre!$I$3:$I$566,Social_Pre!$A$3:$A$566,H19) -> 0 | J19: =SUMIFS(Social_Post!$I$3:$I$566,Social_Post!$A$3:$A$566,H19) -> 0 | K19: =I19/SUM(Question_Bank!$M$3:$M$14) -> 0 | L19: =J19/SUM(Question_Bank!$M$3:$M$14) -> 0 | M19: =J19-I19 -> 0 | N19: =(L19-K19)*100 -> 0 | O19: =IF(M19>=$B$23,"Substantial",IF(M19>=$B$24,"Modest",IF(M19=0,"Unchanged","Lower"))) -> 0 | P19: Lakshmi Das
H20: SM017 | I20: =SUMIFS(Social_Pre!$I$3:$I$566,Social_Pre!$A$3:$A$566,H20) -> 0 | J20: =SUMIFS(Social_Post!$I$3:$I$566,Social_Post!$A$3:$A$566,H20) -> 0 | K20: =I20/SUM(Question_Bank!$M$3:$M$14) -> 0 | L20: =J20/SUM(Question_Bank!$M$3:$M$14) -> 0 | M20: =J20-I20 -> 0 | N20: =(L20-K20)*100 -> 0 | O20: =IF(M20>=$B$23,"Substantial",IF(M20>=$B$24,"Modest",IF(M20=0,"Unchanged","Lower"))) -> 0 | P20: Meera Sharma
H21: SM018 | I21: =SUMIFS(Social_Pre!$I$3:$I$566,Social_Pre!$A$3:$A$566,H21) -> 0 | J21: =SUMIFS(Social_Post!$I$3:$I$566,Social_Post!$A$3:$A$566,H21) -> 0 | K21: =I21/SUM(Question_Bank!$M$3:$M$14) -> 0 | L21: =J21/SUM(Question_Bank!$M$3:$M$14) -> 0 | M21: =J21-I21 -> 0 | N21: =(L21-K21)*100 -> 0 | O21: =IF(M21>=$B$23,"Substantial",IF(M21>=$B$24,"Modest",IF(M21=0,"Unchanged","Lower"))) -> 0 | P21: Anjali Chopra
A22: Category | B22: Min change (points) | C22: Participants | D22: Share | H22: SM019 | I22: =SUMIFS(Social_Pre!$I$3:$I$566,Social_Pre!$A$3:$A$566,H22) -> 0 | J22: =SUMIFS(Social_Post!$I$3:$I$566,Social_Post!$A$3:$A$566,H22) -> 0 | K22: =I22/SUM(Question_Bank!$M$3:$M$14) -> 0 | L22: =J22/SUM(Question_Bank!$M$3:$M$14) -> 0 | M22: =J22-I22 -> 0 | N22: =(L22-K22)*100 -> 0 | O22: =IF(M22>=$B$23,"Substantial",IF(M22>=$B$24,"Modest",IF(M22=0,"Unchanged","Lower"))) -> 0 | P22: Siddharth Ghosh
A23: Substantial improvement | B23: 3 | C23: =COUNTIF($M$4:$M$50,">="&B23) -> 0 | D23: =C23/$B$4 -> 0 | H23: SM020 | I23: =SUMIFS(Social_Pre!$I$3:$I$566,Social_Pre!$A$3:$A$566,H23) -> 0 | J23: =SUMIFS(Social_Post!$I$3:$I$566,Social_Post!$A$3:$A$566,H23) -> 0 | K23: =I23/SUM(Question_Bank!$M$3:$M$14) -> 0 | L23: =J23/SUM(Question_Bank!$M$3:$M$14) -> 0 | M23: =J23-I23 -> 0 | N23: =(L23-K23)*100 -> 0 | O23: =IF(M23>=$B$23,"Substantial",IF(M23>=$B$24,"Modest",IF(M23=0,"Unchanged","Lower"))) -> 0 | P23: Harpreet Shetty
A24: Modest improvement | B24: 1 | C24: =COUNTIF($M$4:$M$50,">="&B24)-COUNTIF($M$4:$M$50,">="&B23) -> 0 | D24: =C24/$B$4 -> 0 | H24: SM021 | I24: =SUMIFS(Social_Pre!$I$3:$I$566,Social_Pre!$A$3:$A$566,H24) -> 0 | J24: =SUMIFS(Social_Post!$I$3:$I$566,Social_Post!$A$3:$A$566,H24) -> 0 | K24: =I24/SUM(Question_Bank!$M$3:$M$14) -> 0 | L24: =J24/SUM(Question_Bank!$M$3:$M$14) -> 0 | M24: =J24-I24 -> 0 | N24: =(L24-K24)*100 -> 0 | O24: =IF(M24>=$B$23,"Substantial",IF(M24>=$B$24,"Modest",IF(M24=0,"Unchanged","Lower"))) -> 0 | P24: Tarun Kaur
A25: Unchanged | B25: 0 | C25: =COUNTIF($M$4:$M$50,0) -> 0 | D25: =C25/$B$4 -> 0 | H25: SM022 | I25: =SUMIFS(Social_Pre!$I$3:$I$566,Social_Pre!$A$3:$A$566,H25) -> 0 | J25: =SUMIFS(Social_Post!$I$3:$I$566,Social_Post!$A$3:$A$566,H25) -> 0 | K25: =I25/SUM(Question_Bank!$M$3:$M$14) -> 0 | L25: =J25/SUM(Question_Bank!$M$3:$M$14) -> 0 | M25: =J25-I25 -> 0 | N25: =(L25-K25)*100 -> 0 | O25: =IF(M25>=$B$23,"Substantial",IF(M25>=$B$24,"Modest",IF(M25=0,"Unchanged","Lower"))) -> 0 | P25: Fatima Thakur
A26: Scored lower | B26: <0 | C26: =COUNTIF($M$4:$M$50,"<0") -> 0 | D26: =C26/$B$4 -> 0 | H26: SM023 | I26: =SUMIFS(Social_Pre!$I$3:$I$566,Social_Pre!$A$3:$A$566,H26) -> 0 | J26: =SUMIFS(Social_Post!$I$3:$I$566,Social_Post!$A$3:$A$566,H26) -> 0 | K26: =I26/SUM(Question_Bank!$M$3:$M$14) -> 0 | L26: =J26/SUM(Question_Bank!$M$3:$M$14) -> 0 | M26: =J26-I26 -> 0 | N26: =(L26-K26)*100 -> 0 | O26: =IF(M26>=$B$23,"Substantial",IF(M26>=$B$24,"Modest",IF(M26=0,"Unchanged","Lower"))) -> 0 | P26: Pooja Gupta
H27: SM024 | I27: =SUMIFS(Social_Pre!$I$3:$I$566,Social_Pre!$A$3:$A$566,H27) -> 0 | J27: =SUMIFS(Social_Post!$I$3:$I$566,Social_Post!$A$3:$A$566,H27) -> 0 | K27: =I27/SUM(Question_Bank!$M$3:$M$14) -> 0 | L27: =J27/SUM(Question_Bank!$M$3:$M$14) -> 0 | M27: =J27-I27 -> 0 | N27: =(L27-K27)*100 -> 0 | O27: =IF(M27>=$B$23,"Substantial",IF(M27>=$B$24,"Modest",IF(M27=0,"Unchanged","Lower"))) -> 0 | P27: Fatima Reddy
H28: SM025 | I28: =SUMIFS(Social_Pre!$I$3:$I$566,Social_Pre!$A$3:$A$566,H28) -> 0 | J28: =SUMIFS(Social_Post!$I$3:$I$566,Social_Post!$A$3:$A$566,H28) -> 0 | K28: =I28/SUM(Question_Bank!$M$3:$M$14) -> 0 | L28: =J28/SUM(Question_Bank!$M$3:$M$14) -> 0 | M28: =J28-I28 -> 0 | N28: =(L28-K28)*100 -> 0 | O28: =IF(M28>=$B$23,"Substantial",IF(M28>=$B$24,"Modest",IF(M28=0,"Unchanged","Lower"))) -> 0 | P28: Manoj Khan
A29: Score change (points) | B29: Participants | H29: SM026 | I29: =SUMIFS(Social_Pre!$I$3:$I$566,Social_Pre!$A$3:$A$566,H29) -> 0 | J29: =SUMIFS(Social_Post!$I$3:$I$566,Social_Post!$A$3:$A$566,H29) -> 0 | K29: =I29/SUM(Question_Bank!$M$3:$M$14) -> 0 | L29: =J29/SUM(Question_Bank!$M$3:$M$14) -> 0 | M29: =J29-I29 -> 0 | N29: =(L29-K29)*100 -> 0 | O29: =IF(M29>=$B$23,"Substantial",IF(M29>=$B$24,"Modest",IF(M29=0,"Unchanged","Lower"))) -> 0 | P29: Farah Ghosh
A30: -6 | B30: =COUNTIF($M$4:$M$50,A30) -> 0 | H30: SM027 | I30: =SUMIFS(Social_Pre!$I$3:$I$566,Social_Pre!$A$3:$A$566,H30) -> 0 | J30: =SUMIFS(Social_Post!$I$3:$I$566,Social_Post!$A$3:$A$566,H30) -> 0 | K30: =I30/SUM(Question_Bank!$M$3:$M$14) -> 0 | L30: =J30/SUM(Question_Bank!$M$3:$M$14) -> 0 | M30: =J30-I30 -> 0 | N30: =(L30-K30)*100 -> 0 | O30: =IF(M30>=$B$23,"Substantial",IF(M30>=$B$24,"Modest",IF(M30=0,"Unchanged","Lower"))) -> 0 | P30: Rohan Shah
A31: -5 | B31: =COUNTIF($M$4:$M$50,A31) -> 0 | H31: SM028 | I31: =SUMIFS(Social_Pre!$I$3:$I$566,Social_Pre!$A$3:$A$566,H31) -> 0 | J31: =SUMIFS(Social_Post!$I$3:$I$566,Social_Post!$A$3:$A$566,H31) -> 0 | K31: =I31/SUM(Question_Bank!$M$3:$M$14) -> 0 | L31: =J31/SUM(Question_Bank!$M$3:$M$14) -> 0 | M31: =J31-I31 -> 0 | N31: =(L31-K31)*100 -> 0 | O31: =IF(M31>=$B$23,"Substantial",IF(M31>=$B$24,"Modest",IF(M31=0,"Unchanged","Lower"))) -> 0 | P31: Divya Bhatia
A32: -4 | B32: =COUNTIF($M$4:$M$50,A32) -> 0 | H32: SM029 | I32: =SUMIFS(Social_Pre!$I$3:$I$566,Social_Pre!$A$3:$A$566,H32) -> 0 | J32: =SUMIFS(Social_Post!$I$3:$I$566,Social_Post!$A$3:$A$566,H32) -> 0 | K32: =I32/SUM(Question_Bank!$M$3:$M$14) -> 0 | L32: =J32/SUM(Question_Bank!$M$3:$M$14) -> 0 | M32: =J32-I32 -> 0 | N32: =(L32-K32)*100 -> 0 | O32: =IF(M32>=$B$23,"Substantial",IF(M32>=$B$24,"Modest",IF(M32=0,"Unchanged","Lower"))) -> 0 | P32: Harsh Naidu
A33: -3 | B33: =COUNTIF($M$4:$M$50,A33) -> 0 | H33: SM030 | I33: =SUMIFS(Social_Pre!$I$3:$I$566,Social_Pre!$A$3:$A$566,H33) -> 0 | J33: =SUMIFS(Social_Post!$I$3:$I$566,Social_Post!$A$3:$A$566,H33) -> 0 | K33: =I33/SUM(Question_Bank!$M$3:$M$14) -> 0 | L33: =J33/SUM(Question_Bank!$M$3:$M$14) -> 0 | M33: =J33-I33 -> 0 | N33: =(L33-K33)*100 -> 0 | O33: =IF(M33>=$B$23,"Substantial",IF(M33>=$B$24,"Modest",IF(M33=0,"Unchanged","Lower"))) -> 0 | P33: Harpreet Kaur
A34: -2 | B34: =COUNTIF($M$4:$M$50,A34) -> 0 | H34: SM031 | I34: =SUMIFS(Social_Pre!$I$3:$I$566,Social_Pre!$A$3:$A$566,H34) -> 0 | J34: =SUMIFS(Social_Post!$I$3:$I$566,Social_Post!$A$3:$A$566,H34) -> 0 | K34: =I34/SUM(Question_Bank!$M$3:$M$14) -> 0 | L34: =J34/SUM(Question_Bank!$M$3:$M$14) -> 0 | M34: =J34-I34 -> 0 | N34: =(L34-K34)*100 -> 0 | O34: =IF(M34>=$B$23,"Substantial",IF(M34>=$B$24,"Modest",IF(M34=0,"Unchanged","Lower"))) -> 0 | P34: Pooja Banerjee
A35: -1 | B35: =COUNTIF($M$4:$M$50,A35) -> 0 | H35: SM032 | I35: =SUMIFS(Social_Pre!$I$3:$I$566,Social_Pre!$A$3:$A$566,H35) -> 0 | J35: =SUMIFS(Social_Post!$I$3:$I$566,Social_Post!$A$3:$A$566,H35) -> 0 | K35: =I35/SUM(Question_Bank!$M$3:$M$14) -> 0 | L35: =J35/SUM(Question_Bank!$M$3:$M$14) -> 0 | M35: =J35-I35 -> 0 | N35: =(L35-K35)*100 -> 0 | O35: =IF(M35>=$B$23,"Substantial",IF(M35>=$B$24,"Modest",IF(M35=0,"Unchanged","Lower"))) -> 0 | P35: Neha Das
A36: 0 | B36: =COUNTIF($M$4:$M$50,A36) -> 0 | H36: SM033 | I36: =SUMIFS(Social_Pre!$I$3:$I$566,Social_Pre!$A$3:$A$566,H36) -> 0 | J36: =SUMIFS(Social_Post!$I$3:$I$566,Social_Post!$A$3:$A$566,H36) -> 0 | K36: =I36/SUM(Question_Bank!$M$3:$M$14) -> 0 | L36: =J36/SUM(Question_Bank!$M$3:$M$14) -> 0 | M36: =J36-I36 -> 0 | N36: =(L36-K36)*100 -> 0 | O36: =IF(M36>=$B$23,"Substantial",IF(M36>=$B$24,"Modest",IF(M36=0,"Unchanged","Lower"))) -> 0 | P36: Neha Bhatia
A37: 1 | B37: =COUNTIF($M$4:$M$50,A37) -> 0 | H37: SM034 | I37: =SUMIFS(Social_Pre!$I$3:$I$566,Social_Pre!$A$3:$A$566,H37) -> 0 | J37: =SUMIFS(Social_Post!$I$3:$I$566,Social_Post!$A$3:$A$566,H37) -> 0 | K37: =I37/SUM(Question_Bank!$M$3:$M$14) -> 0 | L37: =J37/SUM(Question_Bank!$M$3:$M$14) -> 0 | M37: =J37-I37 -> 0 | N37: =(L37-K37)*100 -> 0 | O37: =IF(M37>=$B$23,"Substantial",IF(M37>=$B$24,"Modest",IF(M37=0,"Unchanged","Lower"))) -> 0 | P37: Priya Ansari
A38: 2 | B38: =COUNTIF($M$4:$M$50,A38) -> 0 | H38: SM035 | I38: =SUMIFS(Social_Pre!$I$3:$I$566,Social_Pre!$A$3:$A$566,H38) -> 0 | J38: =SUMIFS(Social_Post!$I$3:$I$566,Social_Post!$A$3:$A$566,H38) -> 0 | K38: =I38/SUM(Question_Bank!$M$3:$M$14) -> 0 | L38: =J38/SUM(Question_Bank!$M$3:$M$14) -> 0 | M38: =J38-I38 -> 0 | N38: =(L38-K38)*100 -> 0 | O38: =IF(M38>=$B$23,"Substantial",IF(M38>=$B$24,"Modest",IF(M38=0,"Unchanged","Lower"))) -> 0 | P38: Pooja Thakur
A39: 3 | B39: =COUNTIF($M$4:$M$50,A39) -> 0 | H39: SM036 | I39: =SUMIFS(Social_Pre!$I$3:$I$566,Social_Pre!$A$3:$A$566,H39) -> 0 | J39: =SUMIFS(Social_Post!$I$3:$I$566,Social_Post!$A$3:$A$566,H39) -> 0 | K39: =I39/SUM(Question_Bank!$M$3:$M$14) -> 0 | L39: =J39/SUM(Question_Bank!$M$3:$M$14) -> 0 | M39: =J39-I39 -> 0 | N39: =(L39-K39)*100 -> 0 | O39: =IF(M39>=$B$23,"Substantial",IF(M39>=$B$24,"Modest",IF(M39=0,"Unchanged","Lower"))) -> 0 | P39: Aditya Kaur
